Workbook
Name ErrLogAreaApr: 'Apr 22'!$C:$C
Name ErrLogAreaAug: 'Aug 22'!$C:$C
Name ErrLogAreaDec: 'Dec 22'!$C:$C
Name ErrLogAreaFeb: 'Feb 22'!$C:$C
Name ErrLogAreaJan: 'Jan 22'!$C:$C
Name ErrLogAreaJul: 'Jul 22'!$C:$C
Name ErrLogAreaJun: 'Jun 22'!$C:$C
Name ErrLogAreaMar: 'Mar 22'!$C:$C
Name ErrLogAreaMay: 'May 22'!$C:$C
Name ErrLogAreaNov: 'Nov 22'!$C:$C
Name ErrLogAreaOct: 'Oct 22'!$C:$C
Name ErrLogAreaSep: 'Sep 22'!$C:$C
Name ErrLogDateApr: 'Apr 22'!$B:$B
Name ErrLogDateAug: 'Aug 22'!$B:$B
Name ErrLogDateDec: 'Dec 22'!$B:$B
Name ErrLogDateFeb: 'Feb 22'!$B:$B
Name ErrLogDateJan: 'Jan 22'!$B:$B
Name ErrLogDateJul: 'Jul 22'!$B:$B
Name ErrLogDateJun: 'Jun 22'!$B:$B
Name ErrLogDateMar: 'Mar 22'!$B:$B
Name ErrLogDateMay: 'May 22'!$B:$B
Name ErrLogDateNov: 'Nov 22'!$B:$B
Name ErrLogDateOct: 'Oct 22'!$B:$B
Name ErrLogDateSep: 'Sep 22'!$B:$B
Name ErrLogTypeApr: 'Apr 22'!$H:$H
Name ErrLogTypeAug: 'Aug 22'!$H:$H
Name ErrLogTypeDec: 'Dec 22'!$H:$H
Name ErrLogTypeFeb: 'Feb 22'!$H:$H
Name ErrLogTypeJan: 'Jan 22'!$H:$H
Name ErrLogTypeJul: 'Jul 22'!$H:$H
Name ErrLogTypeJun: 'Jun 22'!$H:$H
Name ErrLogTypeMar: 'Mar 22'!$H:$H
Name ErrLogTypeMay: 'May 22'!$H:$H
Name ErrLogTypeNov: 'Nov 22'!$H:$H
Name ErrLogTypeOct: 'Oct 22'!$H:$H
Name ErrLogTypeSep: 'Sep 22'!$H:$H

Sheet Jan 22
C2: Error Record
C3: 44562
B5: Date | C5: Production Area | D5: Licensed Status | E5: Product | F5: Product Category | G5: When Was Error Detected | H5: Error Type - PPU | I5: Error Type - NAERS | J5: Who Made Error | K5: Who Detected Error | L5: Contributing Factors | M5: GMP Failure Severity | N5: Potential Outcome | O5: Did This Lead To CAPA/RCA | P5: Comments
B7: 44565 | C7: Zone 5 PN | D7: B - Made under Section 10 | E7: adult bag | F7: C - Parenteral Nutrition - adult | G7: C - Check in preparation area | H7: E - Assembly of starting materials | I7: E15 - Incorrect batch number for diluent vials recorded (Assembly) | J7: Op 25 | K7: Op 29 | L7: N - Distraction | M7: Low | N7: None | O7: No | P7: No BN recorded for WFI
B8: 44565 | C8: Zone 5 PN | D8: B - Made under Section 10 | E8: adult bag | F8: C - Parenteral Nutrition - adult | G8: C - Check in preparation area | H8: E - Assembly of starting materials | I8: E7 - Incorrect quantity/volume of diluent assembled (Assembly) | J8: Op 84 | K8: Op 29 | L8: N - Distraction | M8: Low | N8: None | O8: No | P8: No glucose 40% set up
B9: 44565 | C9: Zone 5 PN | D9: B - Made under Section 10 | E9: adult bag | F9: C - Parenteral Nutrition - adult | G9: C - Check in preparation area | H9: E - Assembly of starting materials | I9: E7 - Incorrect quantity/volume of diluent assembled (Assembly) | J9: Op 42 | K9: Op 29 | L9: N - Distraction | M9: Low | N9: None | O9: No | P9: 1 extra smof bottle set up
B10: 44565 | C10: Zone 5 PN | D10: B - Made under Section 10 | E10: Paed Bag | F10: D - Parenteral Nutrition - paed | G10: C - Check in preparation area | H10: E - Assembly of starting materials | I10: E13 - Incorrect batch number for drug vials recorded (Assembly) | J10: Op 43 | K10: Op 29 | L10: N - Distraction | M10: Low | N10: None | O10: No | P10: BN not recorded for Vaminolact
B11: 44565 | C11: Zone 5 PN | D11: B - Made under Section 10 | E11: Paed Bag | F11: D - Parenteral Nutrition - paed | G11: C - Check in preparation area | H11: E - Assembly of starting materials | I11: E3 - Incorrect quantity of drug vials assembled (Assembly) | J11: Op 31 | K11: Op 29 | L11: N - Distraction | M11: Low | N11: None | O11: No | P11: 1 extra vaminolact set up
B12: 44565 | C12: Zone 5 PN | D12: B - Made under Section 10 | E12: Paed Bag | F12: D - Parenteral Nutrition - paed | G12: C - Check in preparation area | H12: E - Assembly of starting materials | I12: E1 - Incorrect drug assembled (Assembly) | J12: Op 105 | K12: Op 29 | L12: N - Distraction | M12: Low | N12: None | O12: No | P12: sodium glycerphosphate set up instead of calcium
B13: 44565 | C13: Zone 5 PN | D13: B - Made under Section 10 | E13: paed fat | F13: D - Parenteral Nutrition - paed | G13: C - Check in preparation area | H13: E - Assembly of starting materials | I13: E3 - Incorrect quantity of drug vials assembled (Assembly) | J13: Op 105 | K13: Op 29 | L13: N - Distraction | M13: Low | N13: None | O13: No | P13: Only set up for 1 bottle, 2 required
B14: 44566 | C14: Zone 5 PN | D14: B - Made under Section 10 | E14: Paed Bag | F14: D - Parenteral Nutrition - paed | G14: C - Check in preparation area | H14: E - Assembly of starting materials | I14: E3 - Incorrect quantity of drug vials assembled (Assembly) | J14: Op 68 | K14: Op 10 | L14: N - Distraction | M14: Low | N14: None | O14: No | P14: not enough potassium acetate set up
B15: 44566 | C15: Zone 5 PN | D15: B - Made under Section 10 | E15: Paed Bag | F15: D - Parenteral Nutrition - paed | G15: C - Check in preparation area | H15: E - Assembly of starting materials | I15: E7 - Incorrect quantity/volume of diluent assembled (Assembly) | J15: Op 68 | K15: Op 10 | L15: N - Distraction | M15: Low | N15: None | O15: No | P15: not enough glucose 50% set up
B16: 44566 | C16: Zone 5 PN | D16: B - Made under Section 10 | E16: adult bag | F16: C - Parenteral Nutrition - adult | G16: C - Check in preparation area | H16: E - Assembly of starting materials | I16: E6 - Incorrect strength of diluent assembled (Assembly) | J16: Op 68 | K16: Op 10 | L16: N - Distraction | M16: Low | N16: None | O16: No | P16: glucose 50% set up instead of 10%
B17: 44566 | C17: Zone 5 PN | D17: B - Made under Section 10 | E17: adult bag | F17: c - Parenteral Nutrition - adult | G17: C - Check in preparation area | H17: E - Assembly of starting materials | I17: E13 - Incorrect batch number for drug vials recorded (Assembly) | J17: Op 68 | K17: Op 10 | L17: N - Distraction | M17: Low | N17: None | O17: No | P17: one of two aminoven BN not recorded
B18: 44566 | C18: Zone 5 PN | D18: B - Made under Section 10 | E18: adult bag | F18: C - Parenteral Nutrition - adult | G18: C - Check in preparation area | H18: E - Assembly of starting materials | I18: E7 - Incorrect quantity/volume of diluent assembled (Assembly) | J18: Op 68 | K18: Op 10 | L18: N - Distraction | M18: Low | N18: None | O18: No | P18: no WFI set up
... B153: 44592 | C153: Zone 5 Cyt | D153: B - Made under Section 10 | E153: Doxorubicin DC beads | F153: B - Cytotoxic paed | G153: C - Check in preparation area | H153: C - Label generation errors | I153: C1 - Incorrect patient details (Label generation) | J153: Op 67 | K153: Op 105 | L153: N - Distraction | M153: Low | N153: None | O153: No | P153: incorrect spelling of patients name

Sheet Feb 22
C2: Error Record
C3: 44593
B5: Date | C5: Production Area | D5: Licensed Status | E5: Product | F5: Product Category | G5: When Was Error Detected | H5: Error Type - PPU | I5: Error Type - NAERS | J5: Who Made Error | K5: Who Detected Error | L5: Contributing Factors | M5: GMP Failure Severity | N5: Potential Outcome | O5: Did This Lead To CAPA/RCA | P5: Comments
B6: 44593 | C6: Zone 5 PN | D6: B - Made under Section 10 | E6: Adult Bag | F6: C - Parenteral Nutrition - adult | G6: C - Check in preparation area | H6: E - Assembly of starting materials | I6: E1 - Incorrect drug assembled (Assembly) | J6: Op 68 | K6: Op 31 | L6: N - Distraction | M6: Low | N6: None | O6: No | P6: Missing vitlipid adult
B7: 44593 | C7: Zone 5 PN | D7: B - Made under Section 10 | E7: Paed Bag | F7: D - Parenteral Nutrition - paed | G7: C - Check in preparation area | H7: E - Assembly of starting materials | I7: E3 - Incorrect quantity of drug vials assembled (Assembly) | J7: Op 68 | K7: Op 31 | L7: N - Distraction | M7: Low | N7: None | O7: No | P7: excess vials of potassium chloride assembled
B8: 44593 | C8: Zone 5 PN | D8: B - Made under Section 10 | E8: Paed Bag | F8: D - Parenteral Nutrition - paed | G8: C - Check in preparation area | H8: E - Assembly of starting materials | I8: E13 - Incorrect batch number for drug vials recorded (Assembly) | J8: Op 23 | K8: Op 10 | L8: N - Distraction | M8: Low | N8: None | O8: No | P8: one of two SMOF batch numbers not recorded
B9: 44593 | C9: Zone 5 PN | D9: B - Made under Section 10 | E9: Fat Bag | F9: D - Parenteral Nutrition - paed | G9: C - Check in preparation area | H9: E - Assembly of starting materials | I9: E3 - Incorrect quantity of drug vials assembled (Assembly) | J9: Op 47 | K9: Op 31 | L9: N - Distraction | M9: Low | N9: None | O9: No | P9: set up for 1 when 2 required
B10: 44594 | C10: Zone 5 PN | D10: B - Made under Section 10 | E10: Adult Bag | F10: C - Parenteral Nutrition - adult | G10: C - Check in preparation area | H10: E - Assembly of starting materials | I10: E7 - Incorrect quantity/volume of diluent assembled (Assembly) | J10: Op 25 | K10: Op 13 | L10: N - Distraction | M10: Low | N10: None | O10: No | P10: missing 1 x 500ml Glucose 50%
B11: 44594 | C11: Zone 5 PN | D11: B - Made under Section 10 | E11: Paed Bag | F11: D - Parenteral Nutrition - paed | G11: C - Check in preparation area | H11: E - Assembly of starting materials | I11: E7 - Incorrect quantity/volume of diluent assembled (Assembly) | J11: Op 75 | K11: Op 13 | L11: N - Distraction | M11: Low | N11: None | O11: No | P11: no glucose 20% set up
B12: 44594 | C12: Zone 5 PN | D12: B - Made under Section 10 | E12: neo bag | F12: D - Parenteral Nutrition - paed | G12: C - Check in preparation area | H12: E - Assembly of starting materials | I12: E15 - Incorrect batch number for diluent vials recorded (Assembly) | J12: Op 25 | K12: Op 13 | L12: N - Distraction | M12: Low | N12: None | O12: No | P12: wrong BN for WFI recorded
B13: 44595 | C13: Zone 5 PN | D13: B - Made under Section 10 | E13: Adult Bag | F13: C - Parenteral Nutrition - adult | G13: C - Check in preparation area | H13: E - Assembly of starting materials | I13: E13 - Incorrect batch number for drug vials recorded (Assembly) | J13: Op 69 | K13: Op 13 | L13: N - Distraction | M13: Low | N13: None | O13: No | P13: only 1 of 2 BN recorded for aminoven
B14: 44595 | C14: Zone 5 PN | D14: B - Made under Section 10 | E14: Paed Bag | F14: D - Parenteral Nutrition - paed | G14: C - Check in preparation area | H14: E - Assembly of starting materials | I14: E15 - Incorrect batch number for diluent vials recorded (Assembly) | J14: Op 69 | K14: Op 13 | L14: N - Distraction | M14: Low | N14: None | O14: No | P14: only 1 of 2 BN recorded for sodium chloride
B15: 44595 | C15: Zone 5 PN | D15: B - Made under Section 10 | E15: Paed Bag | F15: D - Parenteral Nutrition - paed | G15: C - Check in preparation area | H15: E - Assembly of starting materials | I15: E15 - Incorrect batch number for diluent vials recorded (Assembly) | J15: Op 69 | K15: Op 21 | L15: N - Distraction | M15: Low | N15: None | O15: No | P15: only 1 of 2 BN recorded for sodium chloride 30%
B16: 44595 | C16: Zone 5 PN | D16: B - Made under Section 10 | E16: Paed Bag | F16: D - Parenteral Nutrition - paed | G16: C - Check in preparation area | H16: E - Assembly of starting materials | I16: E13 - Incorrect batch number for drug vials recorded (Assembly) | J16: Op 69 | K16: Op 21 | L16: N - Distraction | M16: Low | N16: None | O16: No | P16: incorrect BN for solivito
B17: 44595 | C17: Zone 5 PN | D17: B - Made under Section 10 | E17: Adult Bag | F17: C - Parenteral Nutrition - adult | G17: C - Check in preparation area | H17: E - Assembly of starting materials | I17: E1 - Incorrect drug assembled (Assembly) | J17: Op 69 | K17: Op 13 | L17: N - Distraction | M17: Low | N17: None | O17: No | P17: sodium acetate set up instead of sodium chloride
... B133: 44614 | C133: Zone 5 PN | D133: B - Made under Section 10 | E133: paed fat | F133: D - Parenteral Nutrition - paed | G133: C - Check in preparation area | H133: E - Assembly of starting materials | I133: E3 - Incorrect quantity of drug vials assembled (Assembly) | J133: Op 23 | K133: Op 27 | L133: N - Distraction | M133: Low | N133: None | O133: No | P133: only 1 set of ingredients set up
B134: 44614 | C134: Zone 5 PN | D134: B - Made under Section 10 | E134: Paed Bag | F134: D - Parenteral Nutrition - paed | G134: C - Check in preparation area | H134: E - Assembly of starting materials | I134: E13 - Incorrect batch number for drug vials recorded (Assembly) | K134: Op 13 | L134: N - Distraction | M134: Low | N134: None | O134: No | P134: only 1 of 2 BN recorded for potassium chloride
B135: 44614 | C135: Zone 5 PN | D135: B - Made under Section 10 | E135: Babiven | F135: D - Parenteral Nutrition - paed | G135: C - Check in preparation area | H135: E - Assembly of starting materials | I135: E3 - Incorrect quantity of drug vials assembled (Assembly) | J135: Op 69 | K135: Op 12 | L135: N - Distraction | M135: Low | N135: None | O135: No | P135: not enough solivito or WFI
B136: 44615 | C136: Zone 5 PN | D136: B - Made under Section 10 | E136: Paed Bag | F136: D - Parenteral Nutrition - paed | G136: C - Check in preparation area | H136: E - Assembly of starting materials | I136: E1 - Incorrect drug assembled (Assembly) | J136: Op 68 | K136: Op 27 | L136: N - Distraction | M136: Low | N136: None | O136: No | P136: WFI set up instead of solivito
B137: 44615 | C137: Zone 5 PN | D137: B - Made under Section 10 | E137: Paed Bag | F137: D - Parenteral Nutrition - paed | G137: C - Check in preparation area | H137: E - Assembly of starting materials | I137: E6 - Incorrect strength of diluent assembled (Assembly) | J137: Op 68 | K137: Op 27 | L137: N - Distraction | M137: Low | N137: None | O137: No | P137: Glucose 50% set up instead of 20%
B138: 44616 | C138: Zone 5 PN | D138: B - Made under Section 10 | E138: Adult Bag | F138: C - Parenteral Nutrition - adult | G138: C - Check in preparation area | H138: E - Assembly of starting materials | I138: E13 - Incorrect batch number for drug vials recorded (Assembly) | J138: Op 69 | K138: Op 12 | L138: N - Distraction | M138: Low | N138: None | O138: No | P138: only 1 of 2 BN recorded for addaven
B139: 44616 | C139: Zone 5 PN | D139: B - Made under Section 10 | E139: Adult Bag | F139: C - Parenteral Nutrition - adult | G139: C - Check in preparation area | H139: E - Assembly of starting materials | I139: E15 - Incorrect batch number for diluent vials recorded (Assembly) | J139: Op 69 | K139: Op 12 | L139: N - Distraction | M139: Low | N139: None | O139: No | P139: incorrect BN for Glucose 10%
B140: 44616 | C140: Zone 5 PN | D140: B - Made under Section 10 | E140: Paed Bag | F140: D - Parenteral Nutrition - paed | G140: C - Check in preparation area | H140: E - Assembly of starting materials | I140: E7 - Incorrect quantity/volume of diluent assembled (Assembly) | J140: Op 68 | K140: Op 12 | L140: N - Distraction | M140: Low | N140: None | O140: No | P140: too much WFI set up
B141: 44616 | C141: Zone 5 PN | D141: B - Made under Section 10 | E141: Paed Bag | F141: D - Parenteral Nutrition - paed | G141: C - Check in preparation area | H141: E - Assembly of starting materials | I141: E3 - Incorrect quantity of drug vials assembled (Assembly) | J141: Op 69 | K141: Op 12 | L141: N - Distraction | M141: Low | N141: None | O141: No | P141: only 1 of 2 BN recorded for aminoven
B142: 44616 | C142: Zone 5 PN | D142: B - Made under Section 10 | E142: Paed Bag | F142: D - Parenteral Nutrition - paed | G142: C - Check in preparation area | H142: E - Assembly of starting materials | I142: E13 - Incorrect batch number for drug vials recorded (Assembly) | J142: Op 69 | K142: Op 12 | L142: N - Distraction | M142: Low | N142: None | P142: only 1 of 2 BN recorded for vitlipid adult
B143: 44616 | C143: Zone 5 PN | D143: B - Made under Section 10 | E143: Adult Bag | F143: C - Parenteral Nutrition - adult | G143: C - Check in preparation area | H143: E - Assembly of starting materials | I143: E13 - Incorrect batch number for drug vials recorded (Assembly) | J143: Op 69 | K143: Op 13 | L143: N - Distraction | M143: Low | N143: None | O143: No | P143: only 1 of 2 BN recorded for aminoven
B144: 44616 | C144: Zone 5 PN | D144: B - Made under Section 10 | E144: neonatal bag | F144: D - Parenteral Nutrition - paed | G144: C - Check in preparation area | H144: E - Assembly of starting materials | I144: E13 - Incorrect batch number for drug vials recorded (Assembly) | J144: Op 112 | K144: Op 12 | L144: N - Distraction | M144: Low | N144: None | O144: No | P144: incorrect BN for sodium glycerphos
B145: 44617 | C145: Zone 5 PN | D145: B - Made under Section 10 | E145: Paed Bag | F145: D - Parenteral Nutrition - paed | G145: C - Check in preparation area | H145: E - Assembly of starting materials | I145: E13 - Incorrect batch number for drug vials recorded (Assembly) | J145: Op 69 | K145: Op 13 | L145: N - Distraction | M145: Low | N145: None | O145: No | P145: only 1 of 2 BN for vitlipid
B146: 44617 | C146: Zone 5 PN | D146: B - Made under Section 10 | E146: Adult Bag | F146: C - Parenteral Nutrition - adult | G146: C - Check in preparation area | H146: E - Assembly of starting materials | I146: E1 - Incorrect drug assembled (Assembly) | J146: Op 68 | K146: Op 13 | L146: N - Distraction | M146: Low | N146: None | O146: No | P146: sodium chloride set up instead of calcium chloride
B147: 44617 | C147: Zone 5 PN | D147: B - Made under Section 10 | E147: Paed Bag | F147: D - Parenteral Nutrition - paed | G147: C - Check in preparation area | H147: E - Assembly of starting materials | I147: E13 - Incorrect batch number for drug vials recorded (Assembly) | J147: Op 87 | K147: Op 12 | L147: N - Distraction | M147: Low | N147: None | O147: No | P147: only 1 of 2 BN for potassium chloride
B148: 44615 | C148: Zone 5 AD | D148: B - Made under Section 10 | E148: desferioxamine | F148: F - Other Aseptic Product | G148: C - Check in preparation area | H148: B - Worksheet preparation error | I148: C13 - Incorrect expiry date/time (Label generation) | J148: Op 22 | K148: Op 13 | L148: N - Distraction | M148: Low | N148: None | O148: No | P148: wrong expiry on worksheet
B149: 44617 | C149: Zone 5 AD | D149: B - Made under Section 10 | E149: Ambisome | F149: F - Other Aseptic Product | G149: C - Check in preparation area | H149: C - Label generation errors | I149: C13 - Incorrect expiry date/time (Label generation) | J149: Op 22 | K149: Op 66 | L149: N - Distraction | M149: Low | N149: None | O149: No | P149: incorrect expiry date
B150: 44616 | C150: Zone 5 Cyt | D150: B - Made under Section 10 | E150: infliximab | F150: B - Cytotoxic paed | G150: C - Check in preparation area | H150: E - Assembly of starting materials | I150: E15 - Incorrect batch number for diluent vials recorded (Assembly) | J150: Op 77 | K150: Op 66 | L150: N - Distraction | M150: Low | N150: None | O150: No | P150: only 1 BN recorded for WFI
B151: 44616 | C151: Zone 5 Cyt | D151: B - Made under Section 10 | E151: infliximab | F151: B - Cytotoxic paed | G151: C - Check in preparation area | H151: E - Assembly of starting materials | I151: E13 - Incorrect batch number for drug vials recorded (Assembly) | J151: Op 77 | K151: Op 66 | L151: N - Distraction | M151: Low | N151: None | O151: No | P151: only 1 BN recorded for infliximab
B152: 44616 | C152: Zone 5 Cyt | D152: B - Made under Section 10 | E152: methotrexate IT | F152: B - Cytotoxic paed | G152: C - Check in preparation area | H152: B - Worksheet preparation error | I152: B1 - Incorrect patient name (Worksheet prep) | J152: Op 30 | K152: Op 66 | L152: N - Distraction | M152: Low | N152: None | O152: No | P152: incorrect hospital number on worksheet/labels
B153: 44617 | C153: Zone 5 Cyt | D153: B - Made under Section 10 | E153: cytarabine | F153: B - Cytotoxic paed | G153: C - Check in preparation area | H153: E - Assembly of starting materials | I153: E2 Incorrect strength assembled (Assembly) | J153: Op 103 | K153: Op 105 | L153: N - Distraction | M153: Low | N153: None | O153: No | P153: incorrect vial size set up
B154: 44617 | C154: Zone 5 Cyt | D154: B - Made under Section 10 | E154: methotrexate IT | F154: B - Cytotoxic paed | G154: C - Check in preparation area | H154: B - Worksheet preparation error | I154: C13 - Incorrect expiry date/time (Label generation) | J154: Op 67 | K154: Op 66 | L154: N - Distraction | M154: Low | N154: None | O154: No | P154: incorrect expiry date on worksheet
... B173: 44620 | C173: NCCC | D173: B - Made under Section 10 | E173: Arsenic | F173: A - Cytotoxic adult | G173: C - Check in preparation area | H173: C - Label generation errors | I173: C13 - Incorrect expiry date/time (Label generation) | J173: Op 2 | K173: Op 120 | L173: N - Distraction | M173: Low | N173: None | O173: No | P173: incorrect expiry time on label

Sheet Mar 22
C2: Error Record
C3: 44621
B5: Date | C5: Production Area | D5: Licensed Status | E5: Product | F5: Product Category | G5: When Was Error Detected | H5: Error Type - PPU | I5: Error Type - NAERS | J5: Who Made Error | K5: Who Detected Error | L5: Contributing Factors | M5: GMP Failure Severity | N5: Potential Outcome | O5: Did This Lead To CAPA/RCA | P5: Comments
B6: 44622 | C6: Zone 5 PN | D6: B - Made under Section 10 | E6: A10 Adult | F6: C - Parenteral Nutrition - adult | G6: C - Check in preparation area | H6: B - Worksheet preparation error | I6: B3 - Incorrect dosage calculation (Worksheet prep) | J6: Op 23 | K6: Op 4 | L6: N - Distraction | M6: Low | N6: None | O6: No | P6: too much magnesium sulphate
B7: 44622 | C7: Zone 5 PN | D7: B - Made under Section 10 | E7: Paed Bag | F7: D - Parenteral Nutrition - paed | G7: C - Check in preparation area | H7: E - Assembly of starting materials | I7: E15 - Incorrect batch number for diluent vials recorded (Assembly) | J7: Op 51 | K7: Op 13 | L7: N - Distraction | M7: Low | N7: None | O7: No | P7: only 1 of 2 BN recorded for Glucose 50%
B8: 44622 | C8: Zone 5 PN | D8: B - Made under Section 10 | E8: fat | F8: D - Parenteral Nutrition - paed | G8: C - Check in preparation area | H8: E - Assembly of starting materials | I8: E3 - Incorrect quantity of drug vials assembled (Assembly) | J8: Op 46 | K8: Op 13 | L8: N - Distraction | M8: Low | N8: None | O8: No | P8: only set up 1 needed 2
B9: 44623 | C9: Zone 5 PN | D9: B - Made under Section 10 | E9: adult bag | F9: C - Parenteral Nutrition - adult | G9: C - Check in preparation area | H9: E - Assembly of starting materials | I9: E15 - Incorrect batch number for diluent vials recorded (Assembly) | J9: Op 69 | K9: Op 21 | L9: N - Distraction | M9: Low | N9: None | O9: No | P9: incorrect BN for Glucose 10%
B10: 44623 | C10: Zone 5 PN | D10: B - Made under Section 10 | E10: adult bag | F10: C - Parenteral Nutrition - adult | G10: C - Check in preparation area | H10: E - Assembly of starting materials | I10: E13 - Incorrect batch number for drug vials recorded (Assembly) | J10: Op 69 | K10: Op 21 | L10: N - Distraction | M10: Low | N10: None | O10: No | P10: missing BN for potassium chloride
B11: 44623 | C11: Zone 5 PN | D11: B - Made under Section 10 | E11: Paed Bag | F11: D - Parenteral Nutrition - paed | G11: C - Check in preparation area | H11: E - Assembly of starting materials | I11: E1 - Incorrect drug assembled (Assembly) | J11: Op 69 | K11: Op 31 | L11: N - Distraction | M11: Low | N11: None | O11: No | P11: sodium chloride set up instead of sodium acetate
B12: 44623 | C12: Zone 5 PN | D12: B - Made under Section 10 | E12: Paed Bag | F12: D - Parenteral Nutrition - paed | G12: C - Check in preparation area | H12: E - Assembly of starting materials | I12: E13 - Incorrect batch number for drug vials recorded (Assembly) | J12: Op 39 | K12: Op 13 | L12: N - Distraction | M12: Low | N12: None | O12: No | P12: only 1 of 2 BN recorded for peditrace
B13: 44624 | C13: Zone 5 PN | D13: B - Made under Section 10 | E13: Paed Bag | F13: D - Parenteral Nutrition - paed | G13: C - Check in preparation area | H13: E - Assembly of starting materials | I13: E3 - Incorrect quantity of drug vials assembled (Assembly) | J13: Op 68 | K13: Op 13 | L13: N - Distraction | M13: Low | N13: None | O13: No | P13: too much vitlipid set up
B14: 44624 | C14: Zone 5 PN | D14: B - Made under Section 10 | E14: Paed Bag | F14: D - Parenteral Nutrition - paed | G14: C - Check in preparation area | H14: E - Assembly of starting materials | I14: E7 - Incorrect quantity/volume of diluent assembled (Assembly) | J14: Op 25 | K14: Op 13 | L14: N - Distraction | M14: Low | N14: None | O14: No | P14: not enough glucose 50% set up
B15: 44624 | C15: Zone 5 PN | D15: B - Made under Section 10 | E15: Paed Bag | F15: D - Parenteral Nutrition - paed | G15: C - Check in preparation area | H15: E - Assembly of starting materials | I15: E3 - Incorrect quantity of drug vials assembled (Assembly) | J15: Op 69 | K15: Op 13 | L15: N - Distraction | M15: Low | N15: None | O15: No | P15: not enough potassium chloride and potassium acetate set up
B16: 44624 | C16: Zone 5 PN | D16: B - Made under Section 10 | E16: Paed Bag | F16: D - Parenteral Nutrition - paed | G16: C - Check in preparation area | H16: E - Assembly of starting materials | I16: E13 - Incorrect batch number for drug vials recorded (Assembly) | J16: Op 69 | K16: Op 18 | L16: N - Distraction | M16: Low | N16: None | O16: No | P16: missing BN for peditrace
B17: 44622 | C17: Zone 5 Cyt | D17: B - Made under Section 10 | E17: etoposide | F17: B - Cytotoxic paed | G17: C - Check in preparation area | H17: E - Assembly of starting materials | I17: E2 Incorrect strength assembled (Assembly) | J17: Op 77 | K17: Op 66 | L17: N - Distraction | M17: Low | N17: None | O17: No | P17: incorrect vial size of etoposide
... B120: 44644 | C120: NCCC | D120: B - Made under Section 10 | E120: paclitaxel | F120: A - Cytotoxic adult | G120: C - Check in preparation area | H120: A - Inaccurate prescription/transcription verification | I120: A1 - Inaccurate prescription/transcription verification (Prescription) | J120: Op 2 | K120: Op 120 | L120: N - Distraction | M120: Low | N120: None | O120: No | P120: incorrect dispensing date on partial prescription
B121: 44634 | C121: Zone 5 Cyt | D121: B - Made under Section 10 | E121: Botox | F121: A - Cytotoxic adult | G121: C - Check in preparation area | H121: C - Label generation errors | I121: C18 - Incorrect quantity of labels (Label generation) | K121: Op 29 | L121: N - Distraction | M121: Low | N121: None | O121: No | P121: incorrect quantity of labels for 2 doses
B122: 44634 | C122: Zone 5 Cyt | D122: B - Made under Section 10 | E122: Doxorubicin LUMI beads | F122: A - Cytotoxic adult | G122: C - Check in preparation area | H122: C - Label generation errors | I122: C13 - Incorrect expiry date/time (Label generation) | J122: Op 67 | K122: Op 29 | L122: N - Distraction | M122: Low | N122: None | O122: No | P122: incorrect expiry date on labels
B123: 44635 | C123: Zone 5 Cyt | D123: B - Made under Section 10 | E123: topical mitomycin | F123: A - Cytotoxic adult | G123: C - Check in preparation area | H123: B - Worksheet preparation error | I123: B10 - Use of incorrect worksheet (Worksheet prep) | J123: Op 29 | K123: Op 12 | L123: N - Distraction | M123: Low | N123: None | O123: No | P123: unlicensed stock syringe worksheet used in error
B124: 44638 | C124: Zone 5 Cyt | D124: B - Made under Section 10 | E124: Methotrexate IT | F124: B - Cytotoxic paed | G124: C - Check in preparation area | H124: C - Label generation errors | I124: C1 - Incorrect patient details (Label generation) | J124: Op 116 | K124: Op 4 | L124: N - Distraction | M124: Low | N124: None | O124: No | P124: incorrect hospital number
B125: 44649 | C125: Zone 3 | D125: A - Made under MS License | E125: Isoniazid elixir | F125: F - Other Aseptic Product | G125: C - Check in preparation area | H125: B - Worksheet preparation error | I125: C13 - Incorrect expiry date/time (Label generation) | J125: Op 79 | K125: Op 27 | L125: N - Distraction | M125: Low | N125: None | O125: No | P125: incorrect expiry allocated
B126: 44648 | C126: Zone 5 PN | D126: B - Made under Section 10 | E126: adult bag | F126: C - Parenteral Nutrition - adult | G126: C - Check in preparation area | H126: E - Assembly of starting materials | I126: E7 - Incorrect quantity/volume of diluent assembled (Assembly) | J126: Op 46 | K126: Op 27 | L126: N - Distraction | M126: Low | N126: None | O126: No | P126: not enough glucose 50% set up
B127: 44650 | C127: Zone 5 PN | D127: B - Made under Section 10 | E127: adult bag | F127: C - Parenteral Nutrition - adult | G127: C - Check in preparation area | H127: E - Assembly of starting materials | I127: E3 - Incorrect quantity of drug vials assembled (Assembly) | J127: Op 39 | K127: Op 27 | L127: N - Distraction | M127: Low | N127: None | O127: No | P127: not enough potassium acetate set up
B128: 44650 | C128: Zone 5 PN | D128: B - Made under Section 10 | E128: adult bag | F128: C - Parenteral Nutrition - adult | G128: C - Check in preparation area | H128: E - Assembly of starting materials | I128: E15 - Incorrect batch number for diluent vials recorded (Assembly) | J128: Op 39 | K128: Op 27 | L128: N - Distraction | M128: Low | N128: None | O128: No | P128: 1 of 2 BN for G40% not recorded
B129: 44650 | C129: Zone 5 PN | D129: B - Made under Section 10 | E129: adult bag | F129: C - Parenteral Nutrition - adult | G129: C - Check in preparation area | H129: E - Assembly of starting materials | I129: E2 Incorrect strength assembled (Assembly) | J129: Op 68 | K129: Op 27 | L129: N - Distraction | M129: Low | N129: None | O129: No | P129: vitlipid infant set up instead of adult
B130: 44650 | C130: Zone 5 PN | D130: B - Made under Section 10 | E130: Paed Bag | F130: D - Parenteral Nutrition - paed | G130: C - Check in preparation area | H130: E - Assembly of starting materials | I130: E15 - Incorrect batch number for diluent vials recorded (Assembly) | J130: Op 103 | K130: Op 27 | L130: N - Distraction | M130: Low | N130: None | O130: No | P130: only 1 of 2 BN for WFI recorded
B131: 44651 | C131: Zone 5 PN | D131: B - Made under Section 10 | E131: Paed Bag | F131: D - Parenteral Nutrition - paed | G131: C - Check in preparation area | H131: E - Assembly of starting materials | I131: E15 - Incorrect batch number for diluent vials recorded (Assembly) | J131: Op 76 | K131: Op 18 | L131: N - Distraction | M131: Low | N131: None | O131: No | P131: only 1 of 2 BN for WFI recorded
B132: 44651 | C132: Zone 5 PN | D132: B - Made under Section 10 | E132: Paed Bag | F132: D - Parenteral Nutrition - paed | G132: C - Check in preparation area | H132: E - Assembly of starting materials | I132: E3 - Incorrect quantity of drug vials assembled (Assembly) | J132: Op 21 | K132: Op 13 | L132: N - Distraction | M132: Low | N132: None | O132: No | P132: too much sodium glycerphosphate set up
B133: 44649 | C133: Zone 5 AD | D133: B - Made under Section 10 | E133: Tazocin allergy | F133: F - Other Aseptic Product | G133: C - Check in preparation area | H133: C - Label generation errors | I133: C4 - Incorrect drug strength (Label generation) | J133: Op 12 | K133: Op 27 | L133: N - Distraction | M133: Low | N133: None | O133: No | P133: incorrect strength of tazocin on label
... B143: 44651 | C143: NCCC | D143: B - Made under Section 10 | E143: etoposide | F143: A - Cytotoxic adult | G143: C - Check in preparation area | H143: C - Label generation errors | I143: C13 - Incorrect expiry date/time (Label generation) | J143: Op 2 | K143: Op 120 | L143: N - Distraction | M143: Low | N143: None | O143: No | P143: incorrect expiry time on label

Sheet Apr 22
C2: Error Record
C3: 44652
B5: Date | C5: Production Area | D5: Licensed Status | E5: Product | F5: Product Category | G5: When Was Error Detected | H5: Error Type - PPU | I5: Error Type - NAERS | J5: Who Made Error | K5: Who Detected Error | L5: Contributing Factors | M5: GMP Failure Severity | N5: Potential Outcome | O5: Did This Lead To CAPA/RCA | P5: Comments
B6: 44652 | C6: Zone 5 PN | D6: B - Made under Section 10 | E6: Adult Bag | F6: C - Parenteral Nutrition - adult | G6: C - Check in preparation area | H6: E - Assembly of starting materials | I6: E1 - Incorrect drug assembled (Assembly) | J6: Op 42 | K6: Op 13 | L6: N - Distraction | M6: Low | N6: None | O6: No | P6: Potassium acetate set up instead of sodium acetate
B7: 44652 | C7: Zone 5 PN | D7: B - Made under Section 10 | E7: Paed Bag | F7: D - Parenteral Nutrition - paed | G7: C - Check in preparation area | H7: E - Assembly of starting materials | I7: E15 - Incorrect batch number for diluent vials recorded (Assembly) | J7: Op 68 | K7: Op 13 | L7: N - Distraction | M7: Low | N7: None | O7: No | P7: only 1 of 2 BN recorded for water
B8: 44652 | C8: Zone 5 PN | D8: B - Made under Section 10 | E8: Paed Bag | F8: D - Parenteral Nutrition - paed | G8: C - Check in preparation area | H8: E - Assembly of starting materials | I8: E3 - Incorrect quantity of drug vials assembled (Assembly) | J8: Op 68 | K8: Op 13 | L8: N - Distraction | M8: Low | N8: None | O8: No | P8: extra peditrace set up
B9: 44652 | C9: Zone 5 PN | D9: B - Made under Section 10 | E9: Paed Bag | F9: D - Parenteral Nutrition - paed | G9: C - Check in preparation area | H9: E - Assembly of starting materials | I9: E3 - Incorrect quantity of drug vials assembled (Assembly) | J9: Op 68 | K9: Op 13 | L9: N - Distraction | M9: Low | N9: None | O9: No | P9: too many vitlipid set up
B10: 44652 | C10: Zone 5 AD | D10: B - Made under Section 10 | E10: Ambisome | F10: F - Other Aseptic Product | G10: C - Check in preparation area | H10: C - Label generation errors | I10: C13 - Incorrect expiry date/time (Label generation) | J10: Op 22 | K10: Op 13 | L10: n - Distraction | M10: Low | N10: None | O10: No | P10: wrong expiry date on ambisome labels
B11: 44652 | C11: Zone 5 Cyt | D11: B - Made under Section 10 | E11: Idarubicin | F11: B - Cytotoxic paed | G11: C - Check in preparation area | H11: E - Assembly of starting materials | I11: E17 - Expired drug used (Assembly) | J11: Op 75 | K11: Op 136 | L11: N - Distraction | M11: Low | N11: None | O11: No | P11: expired vial set up
B12: 44655 | C12: Zone 5 PN | D12: B - Made under Section 10 | E12: Paed Bag | F12: D - Parenteral Nutrition - paed | G12: C - Check in preparation area | H12: E - Assembly of starting materials | I12: E3 - Incorrect quantity of drug vials assembled (Assembly) | J12: Op 68 | K12: Op 27 | L12: N - Distraction | M12: Low | N12: None | O12: No | P12: too much SMOF set up
B13: 44655 | C13: Zone 5 PN | D13: B - Made under Section 10 | E13: fats | F13: D - Parenteral Nutrition - paed | G13: C - Check in preparation area | H13: E - Assembly of starting materials | I13: E3 - Incorrect quantity of drug vials assembled (Assembly) | J13: Op 69 | K13: Op 12 | L13: N - Distraction | M13: Low | N13: None | O13: No | P13: too much Vitlipid Infant
B14: 44655 | C14: Zone 5 PN | D14: B - Made under Section 10 | E14: Paed Bag | F14: D - Parenteral Nutrition - paed | G14: C - Check in preparation area | H14: E - Assembly of starting materials | I14: E3 - Incorrect quantity of drug vials assembled (Assembly) | J14: Op 68 | K14: Op 12 | L14: N - Distraction | M14: Low | N14: None | O14: No | P14: not enough vaminolact
B15: 44655 | C15: Zone 5 PN | D15: B - Made under Section 10 | E15: Paed Bag | F15: D - Parenteral Nutrition - paed | G15: C - Check in preparation area | H15: E - Assembly of starting materials | I15: E13 - Incorrect batch number for drug vials recorded (Assembly) | K15: Op 12 | L15: N - Distraction | M15: Low | N15: None | O15: No | P15: incorrect BN on SMOFlipid
B16: 44655 | C16: Zone 5 PN | D16: B - Made under Section 10 | E16: Paed Bag | F16: D - Parenteral Nutrition - paed | G16: C - Check in preparation area | H16: E - Assembly of starting materials | I16: E1 - Incorrect drug assembled (Assembly) | J16: Op 25 | K16: Op 27 | L16: N - Distraction | M16: Low | N16: None | O16: No | P16: vamin 18EF set up instead of vaminolact
B17: 44656 | C17: Zone 5 PN | D17: B - Made under Section 10 | E17: Paed Bag | F17: D - Parenteral Nutrition - paed | G17: C - Check in preparation area | H17: E - Assembly of starting materials | I17: E3 - Incorrect quantity of drug vials assembled (Assembly) | J17: Op 21 | K17: Op 12 | L17: N - Distraction | M17: Low | N17: None | O17: No | P17: not enough solivito and wfi
B18: 44656 | C18: Zone 5 PN | D18: B - Made under Section 10 | E18: Adult Bag | F18: C - Parenteral Nutrition - adult | G18: C - Check in preparation area | H18: E - Assembly of starting materials | I18: E13 - Incorrect batch number for drug vials recorded (Assembly) | J18: Op 25 | K18: Op 12 | L18: N - Distraction | M18: Low | N18: None | O18: No | P18: only 1 of 2 Bn recorded for cernevit
B19: 44656 | C19: Zone 5 PN | D19: B - Made under Section 10 | E19: Adult Bag | F19: C - Parenteral Nutrition - adult | G19: C - Check in preparation area | H19: E - Assembly of starting materials | I19: E13 - Incorrect batch number for drug vials recorded (Assembly) | J19: Op 69 | K19: Op 12 | L19: N - Distraction | M19: Low | N19: None | O19: No | P19: only 1 of 2 Bn recorded for cernevit
B20: 44656 | C20: Zone 5 PN | D20: B - Made under Section 10 | E20: babiven | F20: D - Parenteral Nutrition - paed | G20: C - Check in preparation area | H20: E - Assembly of starting materials | I20: E15 - Incorrect batch number for diluent vials recorded (Assembly) | J20: Op 25 | K20: Op 12 | L20: N - Distraction | M20: Low | N20: None | O20: No | P20: incorrect BN of WFI recorded
B21: 44657 | C21: Zone 5 PN | D21: B - Made under Section 10 | E21: Paed Bag | F21: D - Parenteral Nutrition - paed | G21: C - Check in preparation area | H21: E - Assembly of starting materials | I21: E15 - Incorrect batch number for diluent vials recorded (Assembly) | J21: Op 51 | K21: Op 66 | L21: N - Distraction | M21: Low | N21: None | O21: No | P21: only 1 BN of 2 recorded for Glucose 70%
B22: 44657 | C22: Zone 5 PN | D22: B - Made under Section 10 | E22: Paed Bag | F22: D - Parenteral Nutrition - paed | G22: C - Check in preparation area | H22: E - Assembly of starting materials | I22: E3 - Incorrect quantity of drug vials assembled (Assembly) | J22: Op 51 | K22: Op 66 | L22: N - Distraction | M22: Low | N22: None | O22: No | P22: not enough potassium chloride set up
B23: 44657 | C23: Zone 5 PN | D23: B - Made under Section 10 | E23: Paed Bag | F23: D - Parenteral Nutrition - paed | G23: C - Check in preparation area | H23: E - Assembly of starting materials | I23: E3 - Incorrect quantity of drug vials assembled (Assembly) | J23: Op 51 | K23: Op 66 | L23: N - Distraction | M23: Low | N23: None | O23: No | P23: not enough magnesium set up
B24: 44657 | C24: Zone 5 PN | D24: B - Made under Section 10 | E24: paed fat | F24: D - Parenteral Nutrition - paed | G24: C - Check in preparation area | H24: E - Assembly of starting materials | I24: E3 - Incorrect quantity of drug vials assembled (Assembly) | J24: Op 84 | K24: Op 13 | L24: N - Distraction | M24: Low | N24: None | O24: No | P24: not enough vitlipid set up
B25: 44659 | C25: Zone 5 PN | D25: B - Made under Section 10 | E25: Paed Bag | F25: D - Parenteral Nutrition - paed | G25: C - Check in preparation area | H25: E - Assembly of starting materials | I25: E3 - Incorrect quantity of drug vials assembled (Assembly) | J25: Op 68 | K25: Op 13 | L25: N - Distraction | M25: Low | N25: None | O25: No | P25: Not enough smof set up
B26: 44659 | C26: Zone 5 PN | D26: B - Made under Section 10 | E26: Paed Bag | F26: D - Parenteral Nutrition - paed | G26: C - Check in preparation area | H26: E - Assembly of starting materials | I26: E15 - Incorrect batch number for diluent vials recorded (Assembly) | J26: Op 69 | K26: Op 13 | L26: N - Distraction | M26: Low | N26: None | O26: No | P26: only 1 of 2 BN recorded for Glucose 50%
B27: 44659 | C27: Zone 5 PN | D27: B - Made under Section 10 | E27: Paed Bag | F27: D - Parenteral Nutrition - paed | G27: C - Check in preparation area | H27: E - Assembly of starting materials | I27: E1 - Incorrect drug assembled (Assembly) | J27: Op 69 | K27: Op 13 | L27: N - Distraction | M27: Low | N27: None | O27: No | P27: smof set up instead of vaminolact
... B91: 44678 | C91: NCCC | D91: B - Made under Section 10 | E91: oxaliplatin | F91: A - Cytotoxic adult | G91: C - Check in preparation area | H91: E - Assembly of starting materials | I91: E1 - Incorrect drug assembled (Assembly) | J91: Op 84 | K91: Op 11 | L91: N - Distraction | M91: Low | N91: None | O91: No | P91: irinotecan vials set up instead of oxaliplatin
B92: 44678 | C92: NCCC | D92: D - Clinical Trial | E92: BT5528 | F92: A - Cytotoxic adult | G92: C - Check in preparation area | H92: C - Label generation errors | I92: C9 - Incorrect batch number for product (Label generation) | K92: Op 23 | L92: N - Distraction | M92: Low | N92: None | O92: No | P92: incorrect BN
B93: 44679 | C93: NCCC | D93: B - Made under Section 10 | E93: fluorouracil | F93: A - Cytotoxic adult | G93: C - Check in preparation area | H93: C - Label generation errors | I93: C1 - Incorrect patient details (Label generation) | J93: Op 2 | K93: Op 61 | L93: N - Distraction | M93: Low | N93: None | O93: No | P93: patient name spelled incorrectly
B94: 44680 | C94: NCCC | D94: B - Made under Section 10 | E94: etoposide | F94: A - Cytotoxic adult | G94: C - Check in preparation area | H94: B - Worksheet preparation error | I94: C13 - Incorrect expiry date/time (Label generation) | J94: Op 118 | K94: Op 120 | L94: N - Distraction | M94: Low | N94: None | O94: No | P94: incorrect expiry time
B95: 44680 | C95: NCCC | D95: B - Made under Section 10 | E95: cisplatin/etoposide | F95: A - Cytotoxic adult | G95: C - Check in preparation area | H95: B - Worksheet preparation error | I95: B10 - Use of incorrect worksheet (Worksheet prep) | J95: Op 118 | K95: Op 120 | L95: N - Distraction | M95: Low | N95: None | O95: No | P95: 2nd pages of worksheet mixed up and stapled to wrong frontsheets
B96: 44680 | C96: NCCC | D96: B - Made under Section 10 | E96: busulfan | F96: A - Cytotoxic adult | G96: C - Check in preparation area | H96: C - Label generation errors | I96: C5 - Incorrect diluent volume (Label generation) | J96: Op 118 | K96: Op 9 | L96: N - Distraction | M96: Low | N96: None | O96: No | P96: wrong volume of sodium chloride
B97: 44678 | C97: NCCC | D97: B - Made under Section 10 | E97: nivolumab | F97: A - Cytotoxic adult | G97: C - Check in preparation area | H97: E - Assembly of starting materials | I97: E13 - Incorrect batch number for drug vials recorded (Assembly) | J97: Op 80 | K97: Op 120 | L97: N - Distraction | M97: Low | N97: None | O97: No | P97: not all batch numbers recorded
B98: 44663 | C98: Zone 5 AD | D98: B - Made under Section 10 | E98: povidone allergy | F98: F - Other Aseptic Product | G98: C - Check in preparation area | H98: B - Worksheet preparation error | I98: B5 - Incorrect volume of diluent (Worksheet prep) | J98: Op 22 | K98: Op 12 | L98: N - Distraction | M98: Low | N98: None | O98: No | P98: too much water transcribed
B99: 44663 | C99: Zone 5 AD | D99: B - Made under Section 10 | E99: dexamethasone allergy | F99: F - Other Aseptic Product | G99: C - Check in preparation area | H99: E - Assembly of starting materials | I99: E18 - Expired diluent used (Assembly) | J99: Op 14 | K99: Op 12 | L99: N - Distraction | M99: Low | N99: None | O99: No | P99: sodium chloride 50ml expired
B100: 44676 | C100: Zone 5 AD | D100: D - Clinical Trial | E100: trial | F100: F - Other Aseptic Product | G100: C - Check in preparation area | H100: E - Assembly of starting materials | I100: E13 - Incorrect batch number for drug vials recorded (Assembly) | J100: Op 76 | K100: Op 29 | L100: N - Distraction | M100: Low | N100: None | O100: No | P100: missing 1 of 2 BN for trial drug
B101: 44677 | C101: Zone 5 AD | D101: B - Made under Section 10 | E101: allergy | F101: F - Other Aseptic Product | G101: C - Check in preparation area | H101: C - Label generation errors | I101: C1 - Incorrect patient details (Label generation) | J101: Op 22 | K101: Op 45 | L101: N - Distraction | M101: Low | N101: None | O101: No | P101: incorrect spelling of name on label
B102: 44677 | C102: Zone 5 AD | D102: B - Made under Section 10 | E102: allergy | F102: F - Other Aseptic Product | G102: C - Check in preparation area | H102: E - Assembly of starting materials | I102: E5 - Incorrect diluent assembled (Assembly) | J102: Op 76 | K102: Op 4 | L102: N - Distraction | M102: Low | N102: None | O102: No | P102: 10ml WFI instead of sodium chloride 0.9%
B103: 44677 | C103: Zone 5 AD | D103: B - Made under Section 10 | E103: allergy CVL | F103: F - Other Aseptic Product | G103: C - Check in preparation area | H103: E - Assembly of starting materials | I103: E14 - Incorrect expiry date for drug vials recorded (Assembly) | J103: Op 76 | K103: Op 120 | L103: N - Distraction | M103: Low | N103: None | O103: No | P103: incorrect expiry date of vial recorded
B104: 44679 | C104: Zone 5 AD | D104: B - Made under Section 10 | E104: allergy | F104: F - Other Aseptic Product | G104: C - Check in preparation area | H104: C - Label generation errors | I104: C1 - Incorrect patient details (Label generation) | J104: Op 22 | K104: Op 13 | L104: N - Distraction | M104: Low | N104: None | O104: No | P104: wrong patient name on labels
... B110: 44664 | C110: Zone 5 PN | D110: B - Made under Section 10 | E110: Paed Bag | F110: D - Parenteral Nutrition - paed | G110: C - Check in preparation area | H110: E - Assembly of starting materials | I110: E1 - Incorrect drug assembled (Assembly) | J110: Op 51 | K110: Op 13 | L110: n - Distraction | M110: Low | N110: None | O110: No | P110: sodium acetate set up instead of magnesium

Sheet May 22
C2: Error Record
C3: 44682
B5: Date | C5: Production Area | D5: Licensed Status | E5: Product | F5: Product Category | G5: When Was Error Detected | H5: Error Type - PPU | I5: Error Type - NAERS | J5: Who Made Error | K5: Who Detected Error | L5: Contributing Factors | M5: GMP Failure Severity | N5: Potential Outcome | O5: Did This Lead To CAPA/RCA | P5: Comments
B6: 44685 | C6: Zone 5 PN | D6: B - Made under Section 10 | E6: Paed Bag | F6: D - Parenteral Nutrition - paed | G6: C - Check in preparation area | H6: E - Assembly of starting materials | I6: E7 - Incorrect quantity/volume of diluent assembled (Assembly) | J6: Op 46 | K6: Op 12 | L6: N - Distraction | M6: Low | N6: None | O6: No | P6: No water with nutratain
B7: 44686 | C7: Zone 5 PN | D7: B - Made under Section 10 | E7: Adult Bag | F7: C - Parenteral Nutrition - adult | G7: C - Check in preparation area | H7: E - Assembly of starting materials | I7: E7 - Incorrect quantity/volume of diluent assembled (Assembly) | J7: Op 46 | K7: Op 21 | L7: N - Distraction | M7: Low | N7: None | O7: No | P7: not enough glucose 20%
B8: 44686 | C8: Zone 5 PN | D8: B - Made under Section 10 | E8: Paed Bag | F8: D - Parenteral Nutrition - paed | G8: C - Check in preparation area | H8: E - Assembly of starting materials | I8: E3 - Incorrect quantity of drug vials assembled (Assembly) | J8: Op 68 | K8: Op 13 | L8: N - Distraction | M8: Low | N8: None | O8: No | P8: not enough SMOF set up
B9: 44686 | C9: Zone 5 PN | D9: B - Made under Section 10 | E9: Paed Bag | F9: D - Parenteral Nutrition - paed | G9: C - Check in preparation area | H9: E - Assembly of starting materials | I9: E13 - Incorrect batch number for drug vials recorded (Assembly) | J9: Op 69 | K9: Op 13 | L9: N - Distraction | M9: Low | N9: None | O9: No | P9: only 1 of 2 BN for Vaminolact recorded
B10: 44686 | C10: Zone 5 PN | D10: B - Made under Section 10 | E10: Fat Bottle | F10: D - Parenteral Nutrition - paed | G10: C - Check in preparation area | H10: E - Assembly of starting materials | I10: E3 - Incorrect quantity of drug vials assembled (Assembly) | J10: Op 69 | K10: Op 9 | L10: N - Distraction | M10: Low | N10: None | O10: No | P10: missing one ampoule
B11: 44686 | C11: Zone 5 PN | D11: B - Made under Section 10 | E11: Fat Bottle | F11: D - Parenteral Nutrition - paed | G11: C - Check in preparation area | H11: E - Assembly of starting materials | I11: E3 - Incorrect quantity of drug vials assembled (Assembly) | J11: Op 69 | K11: Op 9 | L11: N - Distraction | M11: Low | N11: None | O11: No | P11: missing ampoules
B12: 44687 | C12: Zone 5 PN | D12: B - Made under Section 10 | E12: Paed Bag | F12: D - Parenteral Nutrition - paed | G12: C - Check in preparation area | H12: E - Assembly of starting materials | I12: E7 - Incorrect quantity/volume of diluent assembled (Assembly) | J12: Op 69 | K12: Op 13 | L12: N - Distraction | M12: Low | N12: None | O12: No | P12: missing 1 x 50ml glucose 50%
B13: 44687 | C13: Zone 5 PN | D13: B - Made under Section 10 | E13: Paed Bag | F13: D - Parenteral Nutrition - paed | G13: C - Check in preparation area | H13: E - Assembly of starting materials | I13: E13 - Incorrect batch number for drug vials recorded (Assembly) | J13: Op 69 | K13: Op 13 | L13: N - Distraction | M13: Low | N13: None | O13: No | P13: only 1 of 2 BN for Calcium recorded
B14: 44684 | C14: Zone 6 | D14: A - Made under MS License | E14: Voriconazole | F14: F - Other Aseptic Product | G14: C - Check in preparation area | H14: C - Label generation errors | I14: C13 - Incorrect expiry date/time (Label generation) | J14: Op 117 | K14: Op 13 | L14: N - Distraction | M14: Low | N14: None | O14: No | P14: wrong expiry date on labels
B15: 44684 | C15: Zone 6 | D15: A - Made under MS License | E15: Meropenem | F15: F - Other Aseptic Product | G15: C - Check in preparation area | H15: C - Label generation errors | I15: C13 - Incorrect expiry date/time (Label generation) | J15: Op 117 | K15: Op 13 | L15: N - Distraction | M15: Low | N15: None | O15: No | P15: wrong expiry date on labels
B16: 44686 | C16: Zone 6 | D16: A - Made under MS License | E16: colistimethate | F16: F - Other Aseptic Product | G16: C - Check in preparation area | H16: B - Worksheet preparation error | I16: C13 - Incorrect expiry date/time (Label generation) | J16: Op 117 | K16: Op 18 | L16: N - Distraction | M16: Low | N16: None | O16: No | P16: incorrect expiry date
B17: 44686 | C17: Zone 6 | D17: A - Made under MS License | E17: Meropenem | F17: F - Other Aseptic Product | G17: C - Check in preparation area | H17: C - Label generation errors | I17: C11 - Incorrect directions for administration (Label generation) | J17: Op 117 | K17: Op 18 | L17: N - Distraction | M17: Low | N17: None | O17: No | P17: incorrect directions
... B101: 44712 | C101: NCCC | D101: B - Made under Section 10 | E101: Bevacizumab | F101: A - Cytotoxic adult | G101: C - Check in preparation area | H101: E - Assembly of starting materials | I101: E13 - Incorrect batch number for drug vials recorded (Assembly) | J101: Op 35 | K101: Op 120 | L101: N - Distraction | M101: Low | N101: None | O101: No | P101: not all batch numbers recorded

Sheet Jun 22
C2: Error Record
C3: 44713
B5: Date | C5: Production Area | D5: Licensed Status | E5: Product | F5: Product Category | G5: When Was Error Detected | H5: Error Type - PPU | I5: Error Type - NAERS | J5: Who Made Error | K5: Who Detected Error | L5: Contributing Factors | M5: GMP Failure Severity | N5: Potential Outcome | O5: Did This Lead To CAPA/RCA | P5: Comments
B6: 44713 | C6: Zone 5 PN | D6: B - Made under Section 10 | E6: Adult Bag | F6: C - Parenteral Nutrition - adult | G6: C - Check in preparation area | H6: E - Assembly of starting materials | I6: E1 - Incorrect drug assembled (Assembly) | J6: Op 34 | K6: Op 13 | L6: N - Distraction | M6: Low | N6: None | O6: No | P6: potassium chloride set up instead of sodium acetate
B7: 44713 | C7: Zone 5 PN | D7: B - Made under Section 10 | E7: Adult Bag | F7: C - Parenteral Nutrition - adult | G7: C - Check in preparation area | H7: E - Assembly of starting materials | I7: E3 - Incorrect quantity of drug vials assembled (Assembly) | J7: Op 52 | K7: Op 13 | L7: N - Distraction | M7: Low | N7: None | O7: No | P7: extra vitlipid adult set up
B8: 44713 | C8: Zone 5 PN | D8: B - Made under Section 10 | E8: Adult Bag | F8: C - Parenteral Nutrition - adult | G8: C - Check in preparation area | H8: E - Assembly of starting materials | I8: E7 - Incorrect quantity/volume of diluent assembled (Assembly) | J8: Op 52 | K8: Op 13 | L8: N - Distraction | M8: Low | N8: None | O8: No | P8: not enough glucose 50% set up
B9: 44713 | C9: Zone 5 PN | D9: B - Made under Section 10 | E9: Adult Bag | F9: C - Parenteral Nutrition - adult | G9: C - Check in preparation area | H9: E - Assembly of starting materials | I9: E13 - Incorrect batch number for drug vials recorded (Assembly) | J9: Op 52 | K9: Op 13 | L9: N - Distraction | M9: Low | N9: None | O9: No | P9: only 1 of 2 BN recorded for adaven
B10: 44713 | C10: Zone 5 PN | D10: B - Made under Section 10 | E10: Adult Bag | F10: C - Parenteral Nutrition - adult | G10: C - Check in preparation area | H10: E - Assembly of starting materials | I10: E1 - Incorrect drug assembled (Assembly) | J10: Op 52 | K10: Op 13 | L10: N - Distraction | M10: Low | N10: None | O10: No | P10: potassium acetate set up instead of sodium glycerphosphate
B11: 44713 | C11: Zone 5 PN | D11: B - Made under Section 10 | E11: Paed Bag | F11: D - Parenteral Nutrition - paed | G11: C - Check in preparation area | H11: E - Assembly of starting materials | I11: E1 - Incorrect drug assembled (Assembly) | J11: Op 69 | K11: Op 13 | L11: N - Distraction | M11: Low | N11: None | O11: No | P11: potassium acetate set up instead of sodium glycerphosphate
B12: 44713 | C12: Zone 5 AD | D12: B - Made under Section 10 | E12: desferrioxamine dosifusor | F12: F - Other Aseptic Product | G12: C - Check in preparation area | H12: B - Worksheet preparation error | I12: B3 - Incorrect dosage calculation (Worksheet prep) | J12: Op 22 | K12: Op 27 | L12: N - Distraction | M12: Low | N12: None | O12: No | P12: incorrect number of vials calculated
B13: 44713 | C13: Zone 5 AD | D13: B - Made under Section 10 | E13: cerliponase | F13: F - Other Aseptic Product | G13: C - Check in preparation area | H13: C - Label generation errors | I13: C13 - Incorrect expiry date/time (Label generation) | J13: Op 22 | K13: Op 27 | L13: N - Distraction | M13: Low | N13: None | O13: No | P13: incorrect expiry date on label
B14: 44720 | C14: Zone 5 Cyt | D14: B - Made under Section 10 | E14: Cytarabine IT | F14: B - Cytotoxic paed | G14: C - Check in preparation area | H14: E - Assembly of starting materials | I14: E1 - Incorrect drug assembled (Assembly) | J14: Op 39 | K14: Op 9 | L14: N - Distraction | M14: Low | N14: None | O14: No | P14: methotrexate set up instead of cytarabine
B15: 44720 | C15: Zone 5 Cyt | D15: B - Made under Section 10 | E15: Cytarabine IT | F15: B - Cytotoxic paed | G15: C - Check in preparation area | H15: B - Worksheet preparation error | I15: C13 - Incorrect expiry date/time (Label generation) | J15: Op 39 | K15: Op 9 | L15: N - Distraction | M15: Low | N15: None | O15: No | P15: wrong expiry date
B16: 44721 | C16: Zone 5 Cyt | D16: B - Made under Section 10 | E16: carboplatin | F16: B - Cytotoxic paed | G16: C - Check in preparation area | H16: A - Inaccurate prescription/transcription verification | I16: A1 - Inaccurate prescription/transcription verification (Prescription) | J16: Op 67 | K16: Op 83 | L16: N - Distraction | M16: Low | N16: None | O16: No | P16: no clinical check on prescription
B17: 44721 | C17: Zone 5 Cyt | D17: B - Made under Section 10 | E17: Infliximab | F17: B - Cytotoxic paed | G17: C - Check in preparation area | H17: B - Worksheet preparation error | I17: B3 - Incorrect dosage calculation (Worksheet prep) | J17: Op 67 | K17: Op 83 | L17: N - Distraction | M17: Low | N17: None | O17: No | P17: wrong dose on worksheet
... B97: 44736 | C97: Zone 5 PN | D97: B - Made under Section 10 | E97: Paed Bag | F97: D - Parenteral Nutrition - paed | G97: C - Check in preparation area | H97: E - Assembly of starting materials | I97: E15 - Incorrect batch number for diluent vials recorded (Assembly) | J97: Op 69 | K97: Op 61 | L97: N - Distraction | M97: Low | N97: None | O97: No | P97: missing BN for WFI 100ml
B98: 24/06/221 | C98: Zone 5 PN | D98: B - Made under Section 10 | E98: Paed Bag | F98: D - Parenteral Nutrition - paed | G98: C - Check in preparation area | H98: E - Assembly of starting materials | I98: E13 - Incorrect batch number for drug vials recorded (Assembly) | J98: Op 69 | K98: Op 61 | L98: N - Distraction | M98: Low | N98: None | O98: No | P98: missing BN for vitlipid adult
B99: 44736 | C99: Zone 5 PN | D99: B - Made under Section 10 | E99: Paed Bag | F99: D - Parenteral Nutrition - paed | G99: C - Check in preparation area | H99: E - Assembly of starting materials | I99: E15 - Incorrect batch number for diluent vials recorded (Assembly) | J99: Op 69 | K99: Op 61 | L99: N - Distraction | M99: Low | N99: None | O99: No | P99: missing BN for WFI
B100: 44735 | C100: Zone 6 | D100: A - Made under MS License | E100: Meropenem | F100: F - Other Aseptic Product | G100: C - Check in preparation area | H100: E - Assembly of starting materials | I100: E9 - Incorrect volume syringes provided (Assembly) | J100: Op 86 | K100: Op 18 | L100: N - Distraction | M100: Low | N100: None | O100: No | P100: incorrect dosifusor size selected
B101: 44732 | C101: NCCC | D101: B - Made under Section 10 | E101: Etoposide | F101: A - Cytotoxic adult | G101: C - Check in preparation area | H101: C - Label generation errors | I101: C13 - Incorrect expiry date/time (Label generation) | J101: Op 2 | K101: Op 9 | L101: N - Distraction | M101: Low | N101: None | O101: No | P101: wrong expiry time
B102: 44734 | C102: NCCC | D102: D - Clinical Trial | E102: Trial | F102: A - Cytotoxic adult | G102: C - Check in preparation area | H102: C - Label generation errors | I102: C18 - Incorrect quantity of labels (Label generation) | J102: Op 118 | K102: Op 11 | L102: N - Distraction | M102: Low | N102: None | O102: No | P102: insufficient labels produced
B103: 44734 | C103: NCCC | D103: B - Made under Section 10 | E103: Pemetrexed | F103: A - Cytotoxic adult | G103: C - Check in preparation area | H103: E - Assembly of starting materials | I103: E3 - Incorrect quantity of drug vials assembled (Assembly) | J103: Op 75 | K103: Op 11 | L103: N - Distraction | M103: Low | N103: None | O103: No | P103: insufficient vials set up
B104: 44734 | C104: NCCC | D104: B - Made under Section 10 | E104: Etoposide | F104: A - Cytotoxic adult | G104: C - Check in preparation area | H104: B - Worksheet preparation error | I104: C13 - Incorrect expiry date/time (Label generation) | J104: Op 2 | K104: Op 11 | L104: N - Distraction | M104: Low | N104: None | O104: No | P104: incorrect time on worksheet and labels
B105: 44735 | C105: NCCC | D105: B - Made under Section 10 | E105: Bleomycin | F105: A - Cytotoxic adult | G105: C - Check in preparation area | H105: E - Assembly of starting materials | I105: E13 - Incorrect batch number for drug vials recorded (Assembly) | J105: Op 51 | K105: Op 9 | L105: N - Distraction | M105: Low | N105: None | O105: No | P105: incorrect batch number
B106: 44735 | C106: NCCC | D106: B - Made under Section 10 | E106: Docetaxel | F106: A - Cytotoxic adult | G106: C - Check in preparation area | H106: E - Assembly of starting materials | I106: E1 - Incorrect drug assembled (Assembly) | J106: Op 51 | K106: Op 9 | L106: N - Distraction | M106: Low | N106: None | O106: No | P106: incorrect drug selected, etoposide instead of docetaxel
B107: 44735 | C107: NCCC | D107: B - Made under Section 10 | E107: Fluorouracil infusor | F107: A - Cytotoxic adult | G107: C - Check in preparation area | H107: C - Label generation errors | I107: C13 - Incorrect expiry date/time (Label generation) | J107: Op 118 | K107: Op 136 | L107: N - Distraction | M107: Low | N107: None | O107: No | P107: incorrect expiry on label
